
try:
    pass
except Exception as e:
    print(f"случилось {e}")